Workbook

Sheet VISION_BOARD
A1: VISION_BOARD — PANEL DE VISIÓN MAESTRO
J2: KPIs
J3: Objetivos | K3: =COUNTA(A5:A14) -> 10
A4: Categoría | B4: Objetivo 2042 | C4: Imagen / Referencia | D4: Ruta (09_PANEL_VISION) | E4: Fecha incorporación | F4: Estado | G4: Última revisión | H4: Observaciones | J4: Activos | K4: =COUNTIF(F5:F14,"Activo") -> 10
A5: Patrimonio | B5: Casa en Pirque | C5: CASA_PIRQUE.jpg | D5: 09_PANEL_VISION/Casa | F5: Activo | J5: Conseguidos | K5: =COUNTIF(F5:F14,"Conseguido") -> 0
A6: Empresas | B6: Oficina Alonso de Córdova | C6: OFICINA_ALONSO.jpg | D6: 09_PANEL_VISION/Oficina | F6: Activo | J6: Avance | K6: =IF(K3=0,0,K5/K3) -> 0
A7: Empresas | B7: Miner Global Connect | C7: MGC.jpg | D7: 09_PANEL_VISION/MGC | F7: Activo
A8: Empresas | B8: Latitud Norte Holding | C8: LNH.jpg | D8: 09_PANEL_VISION/LNH | F8: Activo
A9: Salud | B9: Salud y longevidad | C9: SALUD.jpg | D9: 09_PANEL_VISION/Salud | F9: Activo
A10: Familia | B10: Tiempo con la familia | C10: FAMILIA.jpg | D10: 09_PANEL_VISION/Familia | F10: Activo
A11: Finanzas | B11: Patrimonio e inversiones | C11: PATRIMONIO.jpg | D11: 09_PANEL_VISION/Finanzas | F11: Activo
A12: Viajes | B12: Viajes internacionales | C12: VIAJES.jpg | D12: 09_PANEL_VISION/Viajes | F12: Activo
A13: Vehículos | B13: Flota objetivo | C13: VEHICULOS.jpg | D13: 09_PANEL_VISION/Vehiculos | F13: Activo
A14: Legado | B14: Fundación y protectora de animales | C14: LEGADO.jpg | D14: 09_PANEL_VISION/Legado | F14: Activo

Sheet SERPAT TURNOS
A1: SERPAT_TURNOS - MODULO MAESTRO
P3: KPIs
P4: Trabajados | Q4: =COUNTIF(C11:C41,"<>Libre") -> 23
P5: Libres | Q5: =COUNTIF(C11:C41,"Libre") -> 8
P6: Horas | Q6: =SUM(J11:J41) -> 193
A10: Fecha | B10: Día | C10: Turno | D10: Tipo | E10: Salida Casa | F10: Ingreso | G10: Colación | H10: Salida | I10: Llegada Casa | J10: Trabajadas | K10: Nocturnas | L10: Extras | M10: Estado | N10: Observaciones
A11: 2026-07-01 | B11: Mié | C11: M | D11: Mañana | F11: 0.33333333 | H11: 0.70833333 | J11: 9 | K11: =IF(C11="N",8,0) -> 0 | L11: 0 | M11: Pendiente
A12: 2026-07-02 | B12: Jue | C12: T | D12: Tarde | F12: 0.5 | H12: 0.875 | J12: 9 | K12: =IF(C12="N",8,0) -> 0 | L12: 0 | M12: Pendiente
A13: 2026-07-03 | B13: Vie | C13: T | D13: Tarde | F13: 0.5 | H13: 0.875 | J13: 9 | K13: =IF(C13="N",8,0) -> 0 | L13: 0 | M13: Pendiente
A14: 2026-07-04 | B14: Sáb | C14: Libre | D14: Libre | J14: =IF(C14="Libre",0,8) -> 0 | K14: =IF(C14="N",8,0) -> 0 | L14: =MAX(J14-8,0) -> 0 | M14: Pendiente
A15: 2026-07-05 | B15: Dom | C15: M | D15: Mañana | F15: 0.33333333 | H15: 0.6875 | J15: 8.5 | K15: =IF(C15="N",8,0) -> 0 | L15: 0 | M15: Pendiente
A16: 2026-07-06 | B16: Lun | C16: T | D16: Tarde | F16: 0.5 | H16: 0.875 | J16: 9 | K16: =IF(C16="N",8,0) -> 0 | L16: 0 | M16: Pendiente
A17: 2026-07-07 | B17: Mar | C17: T | D17: Tarde | F17: 0.5 | H17: 0.875 | J17: 9 | K17: =IF(C17="N",8,0) -> 0 | L17: 0 | M17: Pendiente
A18: 2026-07-08 | B18: Mié | C18: T | D18: Tarde | F18: 0.5 | H18: 0.875 | J18: 9 | K18: =IF(C18="N",8,0) -> 0 | L18: 0 | M18: Pendiente
A19: 2026-07-09 | B19: Jue | C19: T | D19: Tarde | F19: 0.52083333 | H19: 0.875 | J19: 9 | K19: =IF(C19="N",8,0) -> 0 | L19: 0 | M19: Pendiente
A20: 2026-07-10 | B20: Vie | C20: TEX | D20: Compensado | J20: 0 | K20: =IF(C20="N",8,0) -> 0 | L20: =MAX(J20-8,0) -> 0 | M20: Pendiente
A21: 2026-07-11 | B21: Sáb | C21: Libre | D21: Libre | J21: =IF(C21="Libre",0,8) -> 0 | K21: =IF(C21="N",8,0) -> 0 | L21: =MAX(J21-8,0) -> 0 | M21: Pendiente
A22: 2026-07-12 | B22: Dom | C22: Libre | D22: Libre | J22: =IF(C22="Libre",0,8) -> 0 | K22: =IF(C22="N",8,0) -> 0 | L22: =MAX(J22-8,0) -> 0 | M22: Pendiente
A23: 2026-07-13 | B23: Lun | C23: N | D23: Noche | F23: 0.875 | H23: 0.33333333 | J23: 11 | K23: 9 | L23: 2 | M23: Pendiente
A24: 2026-07-14 | B24: Mar | C24: N | D24: Noche | F24: 0.875 | H24: 0.33333333 | J24: 11 | K24: 9 | L24: 2 | M24: Pendiente
A25: 2026-07-15 | B25: Mié | C25: N | D25: Noche | F25: 0.875 | H25: 0.33333333 | J25: 11 | K25: 9 | L25: 2 | M25: Pendiente
A26: 2026-07-16 | B26: Jue | C26: Libre | D26: Libre | J26: =IF(C26="Libre",0,8) -> 0 | K26: =IF(C26="N",8,0) -> 0 | L26: =MAX(J26-8,0) -> 0 | M26: Pendiente
A27: 2026-07-17 | B27: Vie | C27: T | D27: Tarde | F27: 0.52083333 | H27: 0.875 | J27: 9 | K27: =IF(C27="N",8,0) -> 0 | L27: 0 | M27: Pendiente
A28: 2026-07-18 | B28: Sáb | C28: Libre | D28: Libre | J28: =IF(C28="Libre",0,8) -> 0 | K28: =IF(C28="N",8,0) -> 0 | L28: =MAX(J28-8,0) -> 0 | M28: Pendiente
A29: 2026-07-19 | B29: Dom | C29: N | D29: Noche | F29: 0.875 | H29: 0.33333333 | J29: 11 | K29: 9 | L29: 2 | M29: Pendiente
A30: 2026-07-20 | B30: Lun | C30: Libre | D30: Libre | J30: =IF(C30="Libre",0,8) -> 0 | K30: =IF(C30="N",8,0) -> 0 | L30: =MAX(J30-8,0) -> 0 | M30: Pendiente
A31: 2026-07-21 | B31: Mar | C31: TEX | D31: Compensado | J31: 0 | K31: =IF(C31="N",8,0) -> 0 | L31: =MAX(J31-8,0) -> 0 | M31: Pendiente
A32: 2026-07-22 | B32: Mié | C32: T | D32: Tarde | F32: 0.52083333 | H32: 0.875 | J32: 8.5 | K32: =IF(C32="N",8,0) -> 0 | L32: 0 | M32: Pendiente
A33: 2026-07-23 | B33: Jue | C33: N | D33: Noche | F33: 0.875 | H33: 0.33333333 | J33: 11 | K33: 9 | L33: 2 | M33: Pendiente
A34: 2026-07-24 | B34: Vie | C34: N | D34: Noche | F34: 0.875 | H34: 0.33333333 | J34: 11 | K34: 9 | L34: 2 | M34: Pendiente
A35: 2026-07-25 | B35: Sáb | C35: N | D35: Noche | F35: 0.875 | H35: 0.33333333 | J35: 11 | K35: 9 | L35: 2 | M35: Pendiente
A36: 2026-07-26 | B36: Dom | C36: Libre | D36: Libre | J36: =IF(C36="Libre",0,8) -> 0 | K36: =IF(C36="N",8,0) -> 0 | L36: =MAX(J36-8,0) -> 0 | M36: Pendiente
A37: 2026-07-27 | B37: Lun | C37: TEX | D37: Compensado | J37: 0 | K37: =IF(C37="N",8,0) -> 0 | L37: =MAX(J37-8,0) -> 0 | M37: Pendiente
A38: 2026-07-28 | B38: Mar | C38: Libre | D38: Libre | J38: =IF(C38="Libre",0,8) -> 0 | K38: =IF(C38="N",8,0) -> 0 | L38: =MAX(J38-8,0) -> 0 | M38: Pendiente
A39: 2026-07-29 | B39: Mié | C39: T | D39: Tarde | F39: 0.5 | H39: 0.875 | J39: 9 | K39: =IF(C39="N",8,0) -> 0 | L39: 0 | M39: Pendiente
A40: 2026-07-30 | B40: Jue | C40: T | D40: Tarde | F40: 0.5 | H40: 0.875 | J40: 9 | K40: =IF(C40="N",8,0) -> 0 | L40: 0 | M40: Pendiente
A41: 2026-07-31 | B41: Vie | C41: T | D41: Tarde | F41: 0.5 | H41: 0.875 | J41: 9 | K41: =IF(C41="N",8,0) -> 0 | L41: 0 | M41: Pendiente

Sheet PENDIENTES
A1: PENDIENTES - GESTOR MAESTRO
P2: KPIs
P3: Pendientes | Q3: =COUNTIF(F5:F200,"Pendiente") -> 3
A4: ID | B4: Área | C4: Subárea | D4: Tarea | E4: Prioridad | F4: Estado | G4: Fecha Creación | H4: Fecha Límite | I4: Fecha Cierre | J4: Días Abiertos | K4: Avance % | L4: Evidencia | M4: Observaciones | P4: En proceso | Q4: =COUNTIF(F5:F200,"En proceso") -> 0
A5: P-0001 | B5: Universidad | C5: Cálculo II | E5: Alta | F5: Pendiente | J5: =IF(G5="","",TODAY()-G5) | K5: 0 | P5: Completados | Q5: =COUNTIF(F5:F200,"Completado") -> 0
A6: P-0002 | B6: Salud | C6: Cardiología | E6: Crítica | F6: Pendiente | J6: =IF(G6="","",TODAY()-G6) | K6: 0 | P6: Críticos | Q6: =COUNTIF(E5:E200,"Crítica") -> 1
A7: P-0003 | B7: SERPAT | C7: Turnos | E7: Media | F7: Pendiente | J7: =IF(G7="","",TODAY()-G7) | K7: 0
J8: =IF(G8="","",TODAY()-G8) | K8: 0
J9: =IF(G9="","",TODAY()-G9) | K9: 0
J10: =IF(G10="","",TODAY()-G10) | K10: 0
J11: =IF(G11="","",TODAY()-G11) | K11: 0
J12: =IF(G12="","",TODAY()-G12) | K12: 0
J13: =IF(G13="","",TODAY()-G13) | K13: 0
J14: =IF(G14="","",TODAY()-G14) | K14: 0
J15: =IF(G15="","",TODAY()-G15) | K15: 0
J16: =IF(G16="","",TODAY()-G16) | K16: 0
J17: =IF(G17="","",TODAY()-G17) | K17: 0
J18: =IF(G18="","",TODAY()-G18) | K18: 0
J19: =IF(G19="","",TODAY()-G19) | K19: 0
... J54: =IF(G54="","",TODAY()-G54) | K54: 0

Sheet DESARROLLO_PERSONAL
A1: SISTEMA IDENTIDAD
A3: IDENTIDAD
A4: Misión | B4: Construir una vida extraordinaria mediante disciplina, sistemas, aprendizaje continuo y creación de patrimonio.
A5: Visión 2042 | B5: Holding internacional, patrimonio sólido, salud, liderazgo, legado y libertad.
A6: Propósito | B6: Convertir cada día en capital acumulado para Robinson 2042.
A7: Ley 001 | B7: Nunca romper la cadena. Si no puedes avanzar al 100%, avanza al 20%; si no puedes al 20%, avanza al 5%; nunca cero.
A8: Valores | B8: Disciplina, Integridad, Responsabilidad, Aprendizaje, Perseverancia, Humildad, Familia, Excelencia.
A9: Manifiesto | B9: No improvisar. Ejecutar. Construir. Pensar en décadas, actuar hoy.
A11: BIBLIOTECA MAESTRA
A12: Leyendo | B12: Hábitos Atómicos - James Clear | C12: Columna1 | D12: Columna2 | E12: Columna3 | F12: Columna4 | G12: Columna5 | H12: Columna6 | I12: Columna7 | J12: Columna8
A13: Capítulo Actual | B13: 14
A14: Estado | B14: En progreso
A15: Próximos libros | B15: Los 7 Hábitos; Deep Work; Principios; El Inversor Inteligente; Good to Great; Pensar Rápido Pensar Despacio
A17: HÁBITOS
A18: Lectura | B18: 30 min diarios
A19: Gratitud | B19: Diaria
A20: Visualización | B20: Diaria
A21: Ejercicio | B21: 3-5 veces/semana
A22: Inglés | B22: 30 min diarios
A23: Planificación | B23: Diaria
A25: CARÁCTER
A26: Disciplina | B26: Construir mediante ejecución diaria
A27: Constancia | B27: Nunca romper la cadena
A28: Liderazgo | B28: Predicar con el ejemplo
A29: Comunicación | B29: Mejorar continuamente
A30: Paciencia | B30: Pensar a largo plazo
A31: Autocontrol | B31: Dominar emociones
A32: Orden | B32: Todo tiene un sistema
A33: Resiliencia | B33: Aprender de cada dificultad

Sheet 00_GENERADOR_DIA
A1: 00_GENERADOR_DIA — PARAMETROS Y SALIDA PARA MOTOR EXTERNO
A2: PROPÓSITO | B2: Esta hoja NO calcula el día. Python/Codex leerá parámetros, generará cronograma y escribirá salida aquí.
A3: REGLA | B3: No usar fórmulas largas ni dependencias frágiles. Compatible Excel/WPS.
A5: PARÁMETROS EDITABLES
A6: Campo | B6: Valor | C6: Tipo | D6: Fuente futura | E6: Uso del motor | F6: Observación
A7: Fecha del día | B7: 46200 | C7: Fecha | D7: Manual / 20_Registro_Diario | E7: Define día a generar | F7: Editar para probar otra fecha
A8: Tipo día | B8: Turno de Noche | C8: Lista | D8: 20_Registro_Diario | E8: Activa plantilla de jornada | F8: Turno de Noche / Mañana / Tarde / Libre / TEX
A9: Turno SERPAT | B9: 21:00–08:00 | C9: Texto | D9: Calendario laboral | E9: Arma bloques SERPAT | F9: Completar según Shifter
A10: Semana académica | B10: Semana 4 | C10: Texto | D10: 66_T2_Calendario | E10: Trae contenidos | F10: Motor reemplaza por valor real
A11: Prioridad académica | B11: Probabilidad y Estadística | C11: Texto | D11: 62_T2_Evaluaciones | E11: Define primer ramo | F11: Motor calcula por ponderación/plazo
A12: Evaluación crítica | B12: EV-010 / EV-006 / EV-014 — plazo domingo 28 | C12: Texto | D12: 62_T2_Evaluaciones | E12: Genera recordatorio | F12: Motor trae evaluaciones vigentes
A13: Prioridad empresa | B13: MGC / CaptaPropIA / LNH según seguimiento | C13: Texto | D13: 30/33/70/71/76/82 | E13: Define bloque empresa | F13: Motor trae seguimiento pendiente
A14: Nivel energía | B14: Pendiente | C14: Lista | D14: H02_Registro_Salud | E14: Ajusta intensidad | F14: Alto / Medio / Bajo / Pendiente
A15: Presión / alerta salud | B15: Pendiente | C15: Lista | D15: H03_Presión_Log | E15: Activa salud | F15: Normal / Alta / Pendiente
A16: Cierre de mes | B16: No | C16: Lista | D16: Control mensual | E16: Activa cierre mensual | F16: Sí / No
A18: CRONOGRAMA GENERADO POR MOTOR
A19: Orden | B19: Hora inicio | C19: Hora fin | D19: Área | E19: Bloque | F19: Objetivo / instrucción
A20: 1
A21: 2
A22: 3
A23: 4
A24: 5
A25: 6
A26: 7
A27: 8
A28: 9
A29: 10
A30: 11
A31: 12
... A59: 40
A61: SALIDA DOCUMENTAL — COPIAR A WORD

Sheet 00_MOTOR_VIDA_REAL
A1: 00_MOTOR_VIDA_REAL — MAPA OFICIAL DE FUENTES DEL MOTOR
A2: PROPÓSITO | B2: Esta hoja NO calcula. Define qué hojas del Excel C31 debe leer el motor externo Python/Codex.
A3: REGLA | B3: No usar fórmulas aquí. Solo tabla limpia, estable y compatible con Excel/WPS.
A5: ID | B5: Sección | C5: Hoja fuente C31 | D5: Tipo de dato | E5: Campos esperados | F5: Documento alimentado | G5: Uso del motor | H5: Activo | I5: Obligatorio | J5: Observación
A6: M-001 | B6: Vida Real | C6: 20_Registro_Diario | D6: Registro diario | E6: Fecha; tipo día; turno; observaciones | F6: Vida Real; Ancla | G6: Determina apertura, cierre y tipo de jornada | H6: Sí | I6: Sí | J6: Fuente principal del día
A7: M-002 | B7: KPIs | C7: 21_KPI_Diario | D7: Indicadores | E7: Finanzas; Universidad; Salud; Empresas; Excel; Ancla | F7: Vida Real; Ancla | G7: Ajusta cierre y preguntas correctivas | H7: Sí | I7: Sí | J7: Si KPI bajo, activar Ancla crítica
A8: M-003 | B8: Control mensual | C8: 25_Control_Junio / 02_Control_Junio | D8: Control mensual | E8: Fecha; avance; cumplimiento; observaciones | F8: Vida Real; Cierre mensual | G8: Activa cierre mensual y continuidad | H8: Sí | I8: Sí | J8: Usar la hoja vigente según mes
A9: M-004 | B9: Alertas | C9: 90_Alertas_Correcciones | D9: Alertas | E9: Área; indicador; estado; causa; acción | F9: Vida Real; Ancla | G9: Inserta correcciones obligatorias | H9: Sí | I9: Sí | J9: Alerta crítica sube prioridad
A10: M-005 | B10: Universidad ramos | C10: 61_T2_Ramos / 55_T2_CONTENIDOS | D10: Maestro académico | E10: Ramo; unidad; contenido; prioridad; estado | F10: Vida Real | G10: Define qué estudiar | H10: Sí | I10: Sí | J10: No usar materia genérica
A11: M-006 | B11: Universidad evaluaciones | C11: 62_T2_Evaluaciones / 57_T2_EVALUACIONES | D11: Evaluaciones | E11: ID; ramo; porcentaje; fecha; estado; plazo | F11: Vida Real; Ancla | G11: Genera recordatorios de prueba/entrega | H11: Sí | I11: Sí | J11: Evaluación cercana manda prioridad
A12: M-007 | B12: Universidad bloques | C12: 63_T2_Bloques / 56_T2_BLOQUES | D12: Historial estudio | E12: Fecha; ramo; tema; avance; evidencia | F12: Vida Real | G12: Permite continuar donde quedó | H12: Sí | I12: Sí | J12: Debe completarse después de estudiar
A13: M-008 | B13: Universidad errores | C13: 64_T2_Errores / 58_T2_ERRORES | D13: Banco errores | E13: Ramo; tema; error; causa; corrección; estado | F13: Vida Real; Ancla | G13: Obliga a corregir errores abiertos | H13: Sí | I13: Sí | J13: Errores abiertos se reinsertan
A14: M-009 | B14: Calendario académico | C14: 66_T2_Calendario | D14: Calendario | E14: Fecha; semana; clase; contenido; evaluación | F14: Vida Real | G14: Ubica semana y contenidos exactos | H14: Sí | I14: Sí | J14: Base para materia del día
A15: M-010 | B15: Salud diaria | C15: H02_Registro_Salud | D15: Registro salud | E15: Sueño; energía; síntomas; recuperación | F15: Vida Real; Ancla | G15: Ajusta intensidad y descanso | H15: Sí | I15: Sí | J15: Si falta dato, exigir registro
A16: M-011 | B16: Presión arterial | C16: H03_Presión_Log | D16: Registro presión | E16: Hora; presión; pulso; observación | F16: Vida Real; Ancla | G16: Activa bloque de control médico | H16: Sí | I16: Sí | J16: Prioridad salud si presión alta
... A29: M-024 | B29: Generador día | C29: 00_GENERADOR_DIA | D29: Salida/preview | E29: Parámetros; cronograma; salida | F29: Word; Vida Real | G29: Recibe salida del motor externo | H29: Sí | I29: Sí | J29: El motor escribe aquí

Sheet 00_REGLAS_VIDA_REAL
A1: 00_REGLAS_VIDA_REAL — REGLAS OPERATIVAS DEL MOTOR
A2: PROPÓSITO | B2: Esta hoja NO calcula. Define reglas que Python/Codex aplicará para decidir bloques, prioridades y cronograma.
A3: REGLA | B3: No usar fórmulas aquí. Las reglas son datos estructurados para el motor externo.
A5: ID Regla | B5: Área | C5: Condición | D5: Operador | E5: Valor | F5: Prioridad | G5: Bloques activados | H5: Acción del motor | I5: Activa | J5: Fuente | K5: Resultado esperado | L5: No hacer
A6: R-001 | B6: SERPAT | C6: Tipo día | D6: igual | E6: Turno de Noche | F6: 100 | G6: SER-NOCHE | H6: Generar jornada completa: entrega turno anterior, traslado, sueño, salud, estudio, preparación, traslado, turno, entrega día siguiente y cierre post-turno | I6: Sí | J6: 20_Registro_Diario | K6: Día no se cierra antes de SERPAT | L6: Cerrar a media tarde
A7: R-002 | B7: SERPAT | C7: Tipo día | D7: igual | E7: Turno de Mañana | F7: 90 | G7: SER-MANANA | H7: Generar despertar temprano, preparación, trabajo, recuperación, estudio mínimo y cierre nocturno | I7: Sí | J7: 20_Registro_Diario | K7: Día de mantenimiento bien cerrado | L7: Planificar como día libre
A8: R-003 | B8: SERPAT | C8: Tipo día | D8: igual | E8: Turno de Tarde | F8: 90 | G8: SER-TARDE | H8: Generar estudio/empresas en la mañana, preparación al turno, trabajo y cierre liviano | I8: Sí | J8: 20_Registro_Diario | K8: Universidad antes de fatiga | L8: Dejar lo crítico para la noche
A9: R-004 | B9: SERPAT | C9: Tipo día | D9: igual | E9: Libre | F9: 85 | G9: LIBRE | H9: Generar día profundo: universidad fuerte, finanzas, empresas, salud, Ancla y preparación | I9: Sí | J9: 20_Registro_Diario | K9: Avance fuerte sin dispersión | L9: Dormir o improvisar todo el día
A10: R-005 | B10: SERPAT | C10: Tipo día | D10: igual | E10: TEX | F10: 80 | G10: TEX | H10: Generar día de trabajo extra: mantener cadena mínima y no sobrecargar | I10: Sí | J10: 20_Registro_Diario | K10: Continuidad protegida | L10: Exigir intensidad completa
A11: R-006 | B11: Universidad | C11: Evaluación vence en | D11: menor o igual | E11: 7 días | F11: 98 | G11: UNI-EVAL | H11: Insertar recordatorio de evaluación antes del bloque universitario | I11: Sí | J11: 62_T2_Evaluaciones | K11: No perder plazos | L11: Ocultar evaluaciones cercanas
A12: R-007 | B12: Universidad | C12: Evaluación vence en | D12: menor o igual | E12: 2 días | F12: 100 | G12: UNI-CRITICO | H12: Subir prioridad del ramo, reducir empresas y reforzar entrega/prueba | I12: Sí | J12: 62_T2_Evaluaciones | K12: Riesgo académico controlado | L12: Trabajar empresas primero
A13: R-008 | B13: Universidad | C13: Mayor ponderación | D13: igual | E13: Sí | F13: 95 | G13: UNI-PRIORIDAD | H13: Priorizar ramo de mayor impacto si el plazo es cercano | I13: Sí | J13: 62_T2_Evaluaciones | K13: Estudio alineado con nota | L13: Estudiar por gusto
A14: R-009 | B14: Universidad | C14: Último avance | D14: existe | E14: Sí | F14: 92 | G14: UNI-SEGUIMIENTO | H14: Continuar desde último tema, ejercicio, duda o error registrado | I14: Sí | J14: 63_T2_Bloques | K14: No reiniciar desde cero | L14: Repetir contenido sin memoria
A15: R-010 | B15: Universidad | C15: Error abierto | D15: existe | E15: Sí | F15: 94 | G15: UNI-ERRORES | H15: Insertar corrección de error antes de contenido nuevo | I15: Sí | J15: 64_T2_Errores | K15: Error convertido en aprendizaje | L15: Acumular dudas
A16: R-011 | B16: Salud | C16: Turno | D16: igual | E16: Noche | F16: 95 | G16: SAL-NOCHE | H16: Priorizar sueño, presión, alimentación e hidratación | I16: Sí | J16: H02/H03 | K16: Capital biológico protegido | L16: Sacrificar sueño
A17: R-012 | B17: Salud | C17: Presión | D17: igual | E17: Alta | F17: 100 | G17: SAL-ALERTA | H17: Bajar intensidad, registrar presión, agregar observación y posible acción médica | I17: Sí | J17: H03_Presión_Log | K17: Riesgo salud visible | L17: Forzar el plan
... A27: R-022 | B27: Documento | C27: Salida Word | D27: igual | E27: Siempre | F27: 100 | G27: SALIDA-WORD | H27: Generar texto con hora, objetivo, actividad, registro, continuidad y evidencia | I27: Sí | J27: 00_PLANTILLAS_BLOQUES | K27: Vida Real ejecutable | L27: Resumen genérico

Sheet 00_PLANTILLAS_BLOQUES
A1: 00_PLANTILLAS_BLOQUES — BIBLIOTECA OPERATIVA SIN FÓRMULAS
A2: PROPÓSITO | B2: Biblioteca de bloques. El motor externo selecciona filas según reglas y arma Vida Real.
A3: REGLA | B3: No usar fórmulas aquí. Cada fila debe ser un bloque reutilizable.
A5: ID Bloque | B5: Activo | C5: Tipo día permitido | D5: Orden noche | E5: Orden mañana | F5: Orden tarde | G5: Orden libre | H5: Duración min | I5: Área | J5: Nombre bloque | K5: Objetivo | L5: Actividad paso a paso | M5: Registro obligatorio | N5: Continuidad documental | O5: Evidencia mínima | P5: Materia / contenido | Q5: Evaluación / plazo | R5: Seguimiento requerido | S5: Regla mínimo
A6: SER-ENTREGA | B6: Sí | C6: Turno de Noche | D6: 1 | H6: 20 | I6: SERPAT | J6: SALIDA / ENTREGA DEL TURNO | K6: Cerrar correctamente el turno nocturno anterior. | L6: Entregar novedades; revisar observaciones; guardar elementos personales; salir del recinto. | M6: No corresponde | N6: Capítulo 10 — Sistema Laboral SERPAT | O6: ✓ Turno entregado correctamente. ✓ Sin observaciones pendientes. | P6: No aplica | Q6: No aplica | R6: Registrar mentalmente novedades relevantes. | S6: Si hubo incidente, registrar en cierre.
A7: REC-CASA | B7: Sí | C7: Turno de Noche | D7: 2 | H7: 50 | I7: Salud | J7: TRASLADO · LLEGADA A CASA · PREPARACIÓN DEL DESCANSO | K7: Iniciar recuperación física inmediatamente después del turno. | L7: Trasladarse al domicilio; guardar mochila; retirar uniforme; hidratarse; aseo; cerrar cortinas; preparar dormitorio; acostarse. | M7: No corresponde | N7: Capítulo 6 — Sistema Salud | O7: ✓ Recuperación iniciada. ✓ Dormitorio preparado. | P7: No aplica | Q7: No aplica | R7: No usar redes ni abrir tareas estratégicas. | S7: Resolver solo urgencias reales.
A8: SUE-PRINCIPAL | B8: Sí | C8: Turno de Noche | D8: 3 | H8: 320 | I8: Salud | J8: SUEÑO PRINCIPAL | K8: Recuperar energía para sostener la jornada y/o siguiente turno. | L8: Dormir; teléfono en silencio; dormitorio oscuro; evitar interrupciones. | M8: No corresponde | N8: Capítulo 6 — Sistema Salud | O8: ✓ Sueño principal completado. | P8: No aplica | Q8: No aplica | R8: Registrar horas de sueño al despertar. | S8: Si no se logra dormir, reducir intensidad posterior.
A9: SAL-DESPERTAR | B9: Sí | C9: Todos | D9: 4 | E9: 1 | F9: 1 | G9: 1 | H9: 30 | I9: Salud | J9: DESPERTAR · HIGIENE · CONTROL DE SALUD | K9: Iniciar o reiniciar el día con orden y medición de salud. | L9: Levantarse; tender cama; hidratarse; estirar; ducharse; vestirse; tomar medicamento; medir presión; registrar energía. | M9: H02_Registro_Salud; H03_Presión_Log | N9: Capítulo 6 — Sistema Salud | O9: ✓ Día iniciado correctamente. ✓ Salud registrada. | P9: No aplica | Q9: No aplica | R9: Si presión alta, bajar intensidad y registrar observación. | S9: Si no hay tensiómetro, registrar energía y síntomas.
A10: ALI-DESAYUNO | B10: Sí | C10: Todos | E10: 2 | F10: 2 | G10: 2 | H10: 30 | I10: Salud | J10: DESAYUNO / ALIMENTACIÓN | K10: Preparar energía física para sostener la jornada. | L10: Preparar alimentación; hidratarse; ordenar espacio; evaluar energía posterior. | M10: H02_Registro_Salud | N10: Capítulo 6 — Sistema Salud | O10: ✓ Alimentación registrada. ✓ Hidratación realizada. | P10: No aplica | Q10: No aplica | R10: Registrar alimentación y energía posterior. | S10: Evitar gasto hormiga.
A11: SIS-APERTURA | B11: Sí | C11: Todos | D11: 6 | E11: 3 | F11: 3 | G11: 3 | H11: 20 | I11: Sistema | J11: APERTURA OFICIAL DEL SISTEMA | K11: Conocer el estado real antes de ejecutar. | L11: Abrir Excel C31; revisar Dashboard; KPI Diario; calendario laboral; calendario académico; alertas; finanzas; universidad; empresas; salud. | M11: 20_Registro_Diario; 21_KPI_Diario; 25_Control_Junio / 02_Control_Junio; 90_Alertas_Correcciones | N11: Capítulo 3 — Sistema Excel C31 | O11: ✓ Sistema aperturado. ✓ Prioridades confirmadas. | P11: No aplica | Q11: No aplica | R11: Confirmar prioridad académica, laboral y financiera. | S11: Si no alcanza, registrar objetivo y riesgo mínimo.
A12: EVA-REVISION | B12: Sí | C12: Todos | D12: 7 | E12: 4 | F12: 4 | G12: 4 | H12: 15 | I12: Universidad | J12: RECORDATORIO DE EVALUACIONES | K12: Evitar perder pruebas o entregas con plazo cercano. | L12: Abrir Canvas y 62_T2_Evaluaciones; confirmar estado de evaluaciones; revisar pendiente, enviado o por corregir. | M12: 62_T2_Evaluaciones; 66_T2_Calendario; 90_Alertas_Correcciones | N12: Capítulo 4 — Sistema Universidad | O12: ✓ Plazos confirmados. ✓ Riesgo académico visible. | P12: Según ramos activos. | Q12: Según evaluaciones vigentes. | R12: Anotar estado real: pendiente/enviado/revisar nota. | S12: Si hay pendiente crítico, desplazar empresas.
A13: UNI-PROB | B13: Sí | C13: Todos | D13: 8 | E13: 5 | F13: 5 | G13: 5 | H13: 80 | I13: Universidad | J13: PROBABILIDAD Y ESTADÍSTICA | K13: Trabajar el ramo académico de mayor prioridad o evaluación próxima. | L13: Ingresar a Canvas; abrir contenido de la semana; revisar último avance; resolver ejercicios; corregir errores; registrar dudas y avance. | M13: 61_T2_Ramos; 62_T2_Evaluaciones; 63_T2_Bloques; 64_T2_Errores; 65_T2_Dashboard; 66_T2_Calendario | N13: Capítulo 4 — Sistema Universidad | O13: ✓ Bloque universitario completado. ✓ Errores registrados. ✓ Avance actualizado. | P13: Motor debe traer tema exacto desde 66_T2_Calendario y último avance desde 63_T2_Bloques. | Q13: Motor debe traer evaluación vigente desde 62_T2_Evaluaciones. | R13: Registrar dónde quedé, dudas, errores y próxima acción. | S13: Mínimo 5 ejercicios + 1 error corregido.
A14: UNI-COM | B14: Sí | C14: Todos | D14: 9 | E14: 6 | F14: 6 | G14: 6 | H14: 40 | I14: Universidad | J14: COMUNICACIÓN Y ARGUMENTACIÓN | K14: Mantener continuidad argumentativa y preparar actividades de la semana. | L14: Ingresar a Canvas; revisar instrucciones; leer pauta o rúbrica; organizar actividad; registrar fechas importantes y avance. | M14: 61_T2_Ramos; 62_T2_Evaluaciones; 63_T2_Bloques | N14: Capítulo 4 — Sistema Universidad | O14: ✓ Semana organizada. ✓ Actividades registradas. | P14: Motor debe traer actividad exacta desde Canvas/66 si está registrada. | Q14: Motor debe traer evaluación o tarea vigente. | R14: Registrar pendiente exacto: tesis, argumento, conclusión, formato o entrega. | S14: Si hay entrega cercana, cerrar versión antes de empresas.
A15: UNI-CALC | B15: Sí | C15: Todos | D15: 10 | E15: 7 | F15: 7 | G15: 7 | H15: 30 | I15: Universidad | J15: CÁLCULO II | K15: Mantener continuidad matemática evitando pérdida de ritmo. | L15: Abrir Cuaderno Master; revisar contenido de la semana; resolver ejercicios; registrar errores; verificar procedimiento. | M15: 61_T2_Ramos; 63_T2_Bloques; 64_T2_Errores | N15: Capítulo 4 — Sistema Universidad | O15: ✓ Ejercicios desarrollados. ✓ Registro actualizado. | P15: Motor debe traer tema exacto desde 66_T2_Calendario. | Q15: Si hay evaluación, registrar prioridad. | R15: Registrar ejercicio donde quedé y error principal. | S15: Mínimo 2 ejercicios bien verificados.
A16: UNI-FIS | B16: Sí | C16: Todos | D16: 11 | E16: 8 | F16: 8 | G16: 8 | H16: 25 | I16: Universidad | J16: FÍSICA MECÁNICA | K16: Mantener continuidad física y registrar dudas. | L16: Abrir guía; resolver ejercicios programados; registrar dudas para la siguiente sesión. | M16: 61_T2_Ramos; 63_T2_Bloques; 64_T2_Errores | N16: Capítulo 4 — Sistema Universidad | O16: ✓ Física actualizada. ✓ Registro completado. | P16: Motor debe traer tema exacto desde 66_T2_Calendario. | Q16: Si hay evaluación, registrar avance. | R16: Registrar duda concreta y próximo ejercicio. | S16: Mínimo 1 ejercicio completo.
A17: EMP-MGC | B17: Sí | C17: Todos | D17: 12 | E17: 9 | F17: 9 | G17: 9 | H17: 30 | I17: Empresas | J17: MINER GLOBAL CONNECT — CRM Y SEGUIMIENTO | K17: Mantener viva la red estratégica y la inteligencia comercial minera. | L17: Abrir CRM; revisar contactos activos, seguimientos pendientes, oportunidades y mercado; actualizar próxima acción; no abrir negocios nuevos sin evidencia. | M17: 30_MGC_CRM; 33_Seguimientos; 40_Estudio_Empresas; 70_Mercado_MGC | N17: Sistema Empresas — MGC | O17: ✓ CRM actualizado. ✓ Seguimiento programado. | P17: No aplica | Q17: No aplica | R17: Registrar próximo contacto, fecha y acción exacta. | S17: Si universidad crítica, limitar a continuidad mínima.
A18: EMP-HOLDING | B18: Sí | C18: Todos | D18: 13 | E18: 10 | F18: 10 | G18: 10 | H18: 30 | I18: Empresas | J18: LATITUD NORTE HOLDING / LNR / CAPTAPROPIA | K18: Sincronizar proyectos estratégicos sin dispersión. | L18: Revisar LNH, LNR o CaptaPropIA según prioridad; registrar avance, dificultad y siguiente acción; no abrir nuevas líneas. | M18: 71_Mercado_LNR; 76_CaptaPropIA; 82_LNH_Corporate_System | N18: Sistema Empresas / Holding | O18: ✓ Proyecto actualizado. ✓ Siguiente acción definida. | P18: No aplica | Q18: No aplica | R18: Registrar fase, avance, bloqueo y siguiente paso. | S18: No cambiar planificación semanal por impulso.
A19: FIN-DIARIO | B19: Sí | C19: Todos | D19: 14 | E19: 11 | F19: 11 | G19: 11 | H19: 20 | I19: Finanzas | J19: FINANZAS PERSONALES | K19: Mantener caja, gastos, deuda e inversiones visibles. | L19: Registrar ingresos, gastos, pagos, movimientos bancarios, inversiones, saldo disponible y obligaciones pendientes. | M19: 11_Ingresos; 12_Gastos; 13_Deudas; 18_Conciliacion_Bancaria_V3; 25_Control_Junio / 02_Control_Junio | N19: Capítulo 7 — Sistema Finanzas | O19: ✓ Finanzas sincronizadas. ✓ Caja actualizada. | P19: No aplica | Q19: No aplica | R19: Registrar sin movimiento si no hubo gasto. | S19: Si caja baja, activar alerta de gasto.
A20: SAL-ACTIVIDAD | B20: Sí | C20: Todos | E20: 12 | F20: 12 | G20: 12 | H20: 35 | I20: Salud | J20: ACTIVIDAD FÍSICA · PRESIÓN · ENERGÍA | K20: Proteger capital biológico y reiniciar seguimiento de salud. | L20: Caminar o movilidad; respiración; tomar presión si corresponde; registrar energía, pulso, actividad y observaciones. | M20: H02_Registro_Salud; H03_Presión_Log | N20: Capítulo 6 — Sistema Salud | O20: ✓ Actividad registrada. ✓ Energía medida. | P20: No aplica | Q20: No aplica | R20: Registrar efecto físico y mental. | S20: Si hay presión alta, bajar intensidad.
A21: ANCLA | B21: Sí | C21: Todos | E21: 13 | F21: 13 | G21: 13 | H21: 35 | I21: Ancla | J21: ANCLA MENTAL | K21: Corregir ejecución y preparar mentalmente el siguiente bloque o día. | L21: Abrir Ancla Mental; registrar avance, error, decisión estratégica, riesgo, aprendizaje, foco de mañana y prioridad única. | M21: Ancla Mental; 21_KPI_Diario; 90_Alertas_Correcciones | N21: Sistema Ancla Mental | O21: ✓ Ancla actualizada. ✓ Dirección estratégica definida. | P21: No aplica | Q21: No aplica | R21: Preguntas deben salir del KPI o alerta crítica. | S21: No hacer Ancla genérica si hay alertas.
A22: PREP-MANANA | B22: Sí | C22: Todos | E22: 14 | F22: 14 | G22: 14 | H22: 30 | I22: Sistema | J22: PREPARACIÓN DEL DÍA SIGUIENTE | K22: Dejar preparada la siguiente jornada sin improvisación. | L22: Revisar calendario laboral, calendario académico, evaluaciones, alertas, finanzas y documentos abiertos; definir lista obligatoria del día siguiente. | M22: 66_T2_Calendario; 62_T2_Evaluaciones; 90_Alertas_Correcciones; 20_Registro_Diario | N22: Vida Real / Plan diario | O22: ✓ Día siguiente preparado. ✓ Riesgos visibles. | P22: No aplica | Q22: No aplica | R22: Registrar prioridad única del día siguiente. | S22: No cerrar sin preparar mañana.
A23: SER-PREP | B23: Sí | C23: Turno de Noche | D23: 15 | H23: 10 | I23: SERPAT | J23: PREPARACIÓN PARA SERPAT | K23: Salir del domicilio completamente preparado. | L23: Vestir uniforme; preparar mochila, colación, agua, credencial, llaves, teléfono, cargador; verificar domicilio cerrado. | M23: No corresponde | N23: Capítulo 10 — Sistema Laboral SERPAT | O23: ✓ Todo preparado. ✓ Sin pendientes antes de salir. | P23: No aplica | Q23: No aplica | R23: Verificar salida puntual. | S23: No improvisar antes del turno.
A24: SER-TRASLADO | B24: Sí | C24: Turno de Noche | D24: 16 | H24: 60 | I24: SERPAT | J24: TRASLADO A SERPAT | K24: Llegar con anticipación para iniciar el turno sin improvisaciones. | L24: Salir; trasladarse; evitar distracciones; preparar mentalmente turno; llegar; ingresar; revisar novedades; preparar puesto. | M24: No corresponde | N24: Capítulo 10 — Sistema Laboral SERPAT | O24: ✓ Llegada anticipada. ✓ Novedades revisadas. | P24: No aplica | Q24: No aplica | R24: Registrar mentalmente novedades para entrega. | S24: Prioridad seguridad y puntualidad.
A25: SER-PUESTO | B25: Sí | C25: Turno de Noche | D25: 17 | H25: 40 | I25: SERPAT | J25: PREPARACIÓN OPERACIONAL DEL TURNO | K25: Comenzar el turno completamente preparado. | L25: Revisar servicio, protocolos, equipos, llaves, radio, libro de novedades y elementos de seguridad; recibir turno. | M25: No corresponde | N25: Manual Operacional SERPAT | O25: ✓ Puesto operativo. ✓ Inicio preparado. | P25: No aplica | Q25: No aplica | R25: Aclarar dudas antes del inicio oficial. | S25: No entrar desordenado al servicio.
A26: SER-TURNO-NOCHE | B26: Sí | C26: Turno de Noche | D26: 18 | H26: 660 | I26: SERPAT | J26: SERPAT — TURNO NOCTURNO | K26: Ejecutar turno nocturno con profesionalismo y energía administrada. | L26: Cumplir responsabilidades; mantener atención; hidratarse; consumir colación; registrar mentalmente novedades; conducta profesional. | M26: No corresponde | N26: Sistema Laboral SERPAT | O26: ✓ Turno ejecutado correctamente. ✓ Continuidad operacional. | P26: No aplica | Q26: No aplica | R26: Novedades para entrega del día siguiente. | S26: Sin incidentes atribuibles a gestión personal.
A27: SER-ENTREGA-SIG | B27: Sí | C27: Turno de Noche | D27: 19 | H27: 20 | I27: SERPAT | J27: ENTREGA DEL TURNO — DÍA SIGUIENTE | K27: Cerrar correctamente la jornada laboral asegurando continuidad del servicio. | L27: Informar novedades; entregar puesto; responder consultas; verificar observaciones; despedirse formalmente; salir del recinto. | M27: No corresponde | N27: Sistema Laboral SERPAT | O27: ✓ Turno entregado correctamente. ✓ Sin observaciones pendientes. | P27: No aplica | Q27: No aplica | R27: Registrar si hubo novedad relevante. | S27: No dejar observaciones pendientes.
A28: REC-SIG | B28: Sí | C28: Turno de Noche | D28: 20 | H28: 50 | I28: Salud | J28: TRASLADO · LLEGADA AL DOMICILIO — DÍA SIGUIENTE | K28: Comenzar recuperación posterior al turno. | L28: Trasladarse al domicilio; guardar mochila; separar uniforme; hidratarse; aseo personal; preparar dormitorio. | M28: No corresponde | N28: Capítulo 6 — Sistema Salud | O28: ✓ Recuperación iniciada. ✓ Dormitorio preparado. | P28: No aplica | Q28: No aplica | R28: No abrir tareas estratégicas si hay fatiga. | S28: Priorizar sueño.
A29: CIE-POST | B29: Sí | C29: Turno de Noche | D29: 21 | H29: 10 | I29: Cierre | J29: CIERRE OPERACIONAL POST-TURNO | K29: Cerrar el día con evidencia si la energía lo permite. | L29: Actualizar Registro Diario y KPI; registrar cumplimiento, pendientes, aprendizaje, error, decisión siguiente; abrir Ancla Mental. | M29: 20_Registro_Diario; 21_KPI_Diario; Ancla Mental | N29: Vida Real / Ancla | O29: ✓ Día cerrado o postergado con criterio. | P29: No aplica | Q29: No aplica | R29: Si fatiga alta, postergar al primer bloque operativo. | S29: No registrar apurado.
A30: CIERRE-MES | B30: Sí | C30: Todos | E30: 15 | F30: 15 | G30: 15 | H30: 45 | I30: Cierre mensual | J30: CIERRE DE MES / PREPARACIÓN CIERRE | K30: Preparar o ejecutar cierre mensual según fecha. | L30: Revisar ingresos, gastos, deudas, inversión, conciliación, KPI, alertas, universidad, salud y empresas; registrar conclusiones y pendientes. | M30: 24_KPI_Mensual_V4; 25_Control_Junio / 02_Control_Junio; 90_Alertas_Correcciones; 11_Ingresos; 12_Gastos; 13_Deudas | N30: Cierre mensual | O30: ✓ Cierre mensual preparado o ejecutado. | P30: No aplica | Q30: Fin de mes si corresponde. | R30: Registrar conclusiones y acción correctiva. | S30: No cerrar mes sin revisar finanzas.
A31: CIE-DIA | B31: Sí | C31: Todos | E31: 16 | F31: 16 | G31: 16 | H31: 30 | I31: Cierre | J31: CIERRE OPERACIONAL DEL DÍA | K31: Cerrar la jornada con evidencia completa. | L31: Actualizar Registro Diario y KPI Diario; registrar cumplimiento, porcentaje de ejecución, terminados, pendientes, aprendizaje, corrección y prioridad siguiente. | M31: 20_Registro_Diario; 21_KPI_Diario; Ancla Mental | N31: Vida Real / Ancla | O31: ✓ Día cerrado. ✓ Sistema preparado. | P31: No aplica | Q31: No aplica | R31: Cerrar solo cuando la jornada real terminó. | S31: No cerrar antes de SERPAT si hay turno.

Sheet 03_Objetivos_Metas_V4
A1: OBJETIVOS, METAS Y CAPITAL REAL — MAYO 2026
A3: Objetivo maestro | B3: Instalar el Sistema Robinson: control financiero, universidad manejable, CRM operativo, inteligencia de mercado y capital real.
A5: Área | B5: Meta concreta | C5: Cifra / estándar | D5: Fuente / hoja | E5: Resultado actual | F5: % cumplimiento | G5: Estado | H5: Comentario
A6: Caja mínima | B6: Mantener caja mínima operativa | C6: 100000 | D6: 10_Apertura / 14_Inversiones | E6: =SUM('10_Apertura'!C3:C8)+SUMIFS('14_Inversiones'!G:G,'14_Inversiones'!A:A,">=2026-05-01") -> 15732.92 | F6: =IFERROR(E6/C6,0) -> 0.1573292 | G6: =IF(F6>=1,"🟢 Cumple","🟡 Bajo meta") -> 🟡 Bajo meta | H6: Caja real + caja/inversiones líquidas registradas.
A7: Inversión mínima | B7: Mantener inversión mínima activa | C7: 50000 | D7: 14_Inversiones | E7: =SUM('14_Inversiones'!D5:D103) -> 0 | F7: =IFERROR(E7/C7,0) -> 0 | G7: =IF(F7>=1,"🟢 Cumple","🟡 Bajo meta") -> 🟡 Bajo meta | H7: Meta inicial; puede subir en junio.
A8: Registro financiero | B8: Registrar ingresos y gastos | C8: 1 | D8: 11_Ingresos / 12_Gastos | E8: =IF(COUNTA('12_Gastos'!A5:A403)>0,1,0) -> 1 | F8: =E8/C8 -> 1 | G8: =IF(F8>=1,"🟢 Activo","🔴 Sin registro") -> 🟢 Activo | H8: Debe ser 100% real.
A9: Conciliación | B9: Hacer conciliación semanal | C9: 4 | D9: 15_Conciliacion | G9: Manual | H9: Registrar cada semana al cierre.
A10: Empresas analizadas | B10: Analizar 25 a 40 empresas/contactos | C10: 25 | D10: 40_Estudio_Empresas | E10: =COUNTA('40_Estudio_Empresas'!A3:A202) -> 200 | F10: =IFERROR(E10/C10,0) -> 8 | G10: =IF(F10>=1,"🟢 Cumple","🟡 En construcción") -> 🟢 Cumple | H10: No volumen vacío: calidad.
A11: CRM operativo | B11: CRM con contactos clasificados | C11: 1 | D11: 30_MGC_CRM | E11: =IF(COUNTA('30_MGC_CRM'!E5:E213)>0,1,0) -> 1 | F11: =E11/C11 -> 1 | G11: =IF(F11>=1,"🟢 Activo","🔴 Sin CRM") -> 🟢 Activo | H11: Solo empresas/personas ya evaluadas.
A12: Universidad | B12: Mantener bloques de estudio reales | C12: 12 | D12: 51_Bloques_Estudio | E12: =COUNTA('51_Bloques_Estudio'!A5:A204) -> 95 | F12: =IFERROR(E12/C12,0) -> 7.9166667 | G12: =IF(F12>=1,"🟢 Cumple","🟡 En riesgo") -> 🟢 Cumple | H12: Cálculo y Química primero.
A13: Continuidad | B13: Registrar 20 días o más | C13: 20 | D13: 20_Registro_CEO_V4 | E13: =COUNT('20_Registro_CEO_V4'!K5:K34) -> 28 | F13: =IFERROR(E13/C13,0) -> 1.4 | G13: =IF(F13>=1,"🟢 Fuerte","🟡 Medio") -> 🟢 Fuerte | H13: Una fila por día.

Sheet 94_Auditoria_Operativa_C31
A1: 94 AUDITORÍA OPERATIVA C31 — HOJAS VISIBLES / OCULTAS
A2: Objetivo: dejar encendidas sólo las hojas operativas que se usan en el sistema actual. Las hojas antiguas, históricas, backups, referencias y versiones anteriores quedan ocultas al final.
A4: Total hojas | B4: 148
A5: Hojas visibles operativas | B5: 77
A6: Hojas ocultas / referencia / legacy | B6: 71
A7: Criterio | B7: Visible = uso operativo actual. Oculta = histórico, backup, versión anterior, auditoría vieja, plantilla o referencia.
A10: HOJAS VISIBLES | B10: Bloque | C10: Estado | D10: Motivo | E10: Acción
A11: 94_Auditoria_Operativa_C31 | B11: Control / Auditoría | C11: Visible | D11: Uso operativo actual | E11: Mantener encendida
A12: 00_MAPA_OPERATIVO_FINAL | B12: Control / Auditoría | C12: Visible | D12: Uso operativo actual | E12: Mantener encendida
A13: 00_INDICE_OPERATIVO | B13: Control / Auditoría | C13: Visible | D13: Uso operativo actual | E13: Mantener encendida
A14: SEC_01_CEO_CONTROL | B14: Separador operativo | C14: Visible | D14: Uso operativo actual | E14: Mantener encendida
A15: 04_Score_Ejecutivo_Consolidado | B15: Control / Auditoría | C15: Visible | D15: Uso operativo actual | E15: Mantener encendida
A16: 90_Alertas_Correcciones | B16: Control / Auditoría | C16: Visible | D16: Uso operativo actual | E16: Mantener encendida
A17: SEC_02_FINANZAS | B17: Separador operativo | C17: Visible | D17: Uso operativo actual | E17: Mantener encendida
A18: 09_Posicion_Actual | B18: Control / Auditoría | C18: Visible | D18: Uso operativo actual | E18: Mantener encendida
A19: 10_Patrimonio_Financiero | B19: Finanzas | C19: Visible | D19: Uso operativo actual | E19: Mantener encendida
A20: 11_Ingresos | B20: Finanzas | C20: Visible | D20: Uso operativo actual | E20: Mantener encendida
A21: 12_Gastos | B21: Finanzas | C21: Visible | D21: Uso operativo actual | E21: Mantener encendida
... A160: 93_Auditoria_Conciliacion | B160: Otro | C160: Oculta | D160: Histórico / backup / versión anterior / referencia | E160: Apagada al final

Sheet 00_MAPA_OPERATIVO_FINAL
A1: SECCIÓN
A2: 01_CEO_CONTROL
A3: 01_CEO_CONTROL | B3: 04_Score_Ejecutivo_Consolidado | C3: MAESTRA / OPERATIVA | D3: visible | E3: Control ejecutivo central | F3: Debe permanecer visible dentro del sistema operativo 2026
A4: 01_CEO_CONTROL | B4: 09_Posicion_Actual | C4: MAESTRA / OPERATIVA | D4: visible | E4: Control ejecutivo central | F4: Debe permanecer visible dentro del sistema operativo 2026 | G4: Columna1 | H4: Columna2 | I4: Columna3
A5: 01_CEO_CONTROL | B5: 90_Alertas_Correcciones | C5: MAESTRA / OPERATIVA | D5: visible | E5: Control ejecutivo central | F5: Debe permanecer visible dentro del sistema operativo 2026
A6: 02_FINANZAS | B6: 10_Patrimonio_Financiero | C6: MAESTRA / OPERATIVA | D6: visible | E6: Caja, patrimonio, inversiones, deudas y conciliación | F6: Debe permanecer visible dentro del sistema operativo 2026
A7: 02_FINANZAS | B7: 11_Ingresos | C7: MAESTRA / OPERATIVA | D7: visible | E7: Caja, patrimonio, inversiones, deudas y conciliación | F7: Debe permanecer visible dentro del sistema operativo 2026
A8: 02_FINANZAS | B8: 12_Gastos | C8: MAESTRA / OPERATIVA | D8: visible | E8: Caja, patrimonio, inversiones, deudas y conciliación | F8: Debe permanecer visible dentro del sistema operativo 2026
A9: 02_FINANZAS | B9: 13_Deudas | C9: MAESTRA / OPERATIVA | D9: visible | E9: Caja, patrimonio, inversiones, deudas y conciliación | F9: Debe permanecer visible dentro del sistema operativo 2026
A10: 02_FINANZAS | B10: 14_Inversiones | C10: MAESTRA / OPERATIVA | D10: visible | E10: Caja, patrimonio, inversiones, deudas y conciliación | F10: Debe permanecer visible dentro del sistema operativo 2026
A11: 02_FINANZAS | B11: 18_Conciliacion_Bancaria_V2 | C11: MAESTRA / OPERATIVA | D11: visible | E11: Caja, patrimonio, inversiones, deudas y conciliación | F11: Debe permanecer visible dentro del sistema operativo 2026
A12: 03_VIDA_REAL_SALUD | B12: 20_Registro_Diario | C12: MAESTRA / OPERATIVA | D12: visible | E12: Calidad de vida, energía, cumplimiento, hábitos y Divina Obsesión | F12: Debe permanecer visible dentro del sistema operativo 2026
A13: 03_VIDA_REAL_SALUD | B13: 21_KPI_Diario | C13: MAESTRA / OPERATIVA | D13: visible | E13: Calidad de vida, energía, cumplimiento, hábitos y Divina Obsesión | F13: Debe permanecer visible dentro del sistema operativo 2026
A14: 03_VIDA_REAL_SALUD | B14: 22_KPI_Semanal_V4 | C14: MAESTRA / OPERATIVA | D14: visible | E14: Calidad de vida, energía, cumplimiento, hábitos y Divina Obsesión | F14: Debe permanecer visible dentro del sistema operativo 2026
A15: 03_VIDA_REAL_SALUD | B15: 23_Domingo_CEO | C15: MAESTRA / OPERATIVA | D15: visible | E15: Calidad de vida, energía, cumplimiento, hábitos y Divina Obsesión | F15: Debe permanecer visible dentro del sistema operativo 2026
A16: 03_VIDA_REAL_SALUD | B16: 24_KPI_Mensual_V4 | C16: MAESTRA / OPERATIVA | D16: visible | E16: Calidad de vida, energía, cumplimiento, hábitos y Divina Obsesión | F16: Debe permanecer visible dentro del sistema operativo 2026
... A58: SEPARADOR | B58: SEC_07_LNH_CORPORATE | C58: SECCIÓN | D58: visible | E58: Orden visual por módulos | F58: Separador visible
A60: HOJAS OCULTAS / HISTÓRICAS
A61: HISTÓRICO / OCULTO | B61: 51_Bloques_Estudio | C61: OCULTA | D61: hidden | E61: Respaldo / duplicado / versión anterior | F61: No se elimina información
A62: HISTÓRICO / OCULTO | B62: 54_Ramos_Activos | C62: OCULTA | D62: hidden | E62: Respaldo / duplicado / versión anterior | F62: No se elimina información
A63: HISTÓRICO / OCULTO | B63: 53_Errores_Aprendizaje | C63: OCULTA | D63: hidden | E63: Respaldo / duplicado / versión anterior | F63: No se elimina información
A64: HISTÓRICO / OCULTO | B64: 55_Evaluaciones | C64: OCULTA | D64: hidden | E64: Respaldo / duplicado / versión anterior | F64: No se elimina información
A65: HISTÓRICO / OCULTO | B65: 58_Dashboard_Academico | C65: OCULTA | D65: hidden | E65: Respaldo / duplicado / versión anterior | F65: No se elimina información
A66: HISTÓRICO / OCULTO | B66: CLASIFICACION_MANUAL | C66: OCULTA | D66: hidden | E66: Respaldo / duplicado / versión anterior | F66: No se elimina información
A67: HISTÓRICO / OCULTO | B67: 00_Dashboard_V4 | C67: OCULTA | D67: hidden | E67: Respaldo / duplicado / versión anterior | F67: No se elimina información
A68: HISTÓRICO / OCULTO | B68: FASE_03_LIMPIEZA | C68: OCULTA | D68: hidden | E68: Respaldo / duplicado / versión anterior | F68: No se elimina información
A69: HISTÓRICO / OCULTO | B69: 00_Indice_V6 | C69: OCULTA | D69: hidden | E69: Respaldo / duplicado / versión anterior | F69: No se elimina información
A70: HISTÓRICO / OCULTO | B70: 01_Score_Mayo | C70: OCULTA | D70: hidden | E70: Respaldo / duplicado / versión anterior | F70: No se elimina información
A71: HISTÓRICO / OCULTO | B71: 03_Objetivos_Metas_V4 | C71: OCULTA | D71: hidden | E71: Respaldo / duplicado / versión anterior | F71: No se elimina información
A72: HISTÓRICO / OCULTO | B72: 19_Mapa_Sistema | C72: OCULTA | D72: hidden | E72: Respaldo / duplicado / versión anterior | F72: No se elimina información
... A118: HISTÓRICO / OCULTO | B118: 99_HISTORICO_DEPURADO | C118: OCULTA | D118: hidden | E118: Respaldo / duplicado / versión anterior | F118: No se elimina información

Sheet 00_INDICE_OPERATIVO
A1: FASE O1 - INDICE OPERATIVO
A3: CEO & CONTROL
B4: 20_Registro_Diario
B5: 21_KPI_Diario
B6: 22_KPI_Semanal_V4
B7: 24_KPI_Mensual_V4
B8: AUDITORIA_TOTAL_EXCEL_V7_1
A10: FINANZAS
B11: 11_Ingresos
B12: 12_Gastos
B13: 13_Deudas
B14: 14_Inversiones
B15: 09_Posicion_Actual
B16: 10_Patrimonio_Financiero
B17: 18_Conciliacion_Bancaria_V2
A19: UNIVERSIDAD
B20: 50_Universidad_Master
B21: 54_Ramos_Activos
B22: 55_Evaluaciones
B23: 56_Notas
B24: 57_Matriz_Prioridad
B25: 58_Dashboard_Academico
B26: 59_Control_Trimestral
A28: EMPRESAS
B29: 30_MGC_CRM
B30: 31_Red_Holding
B31: 32_Oportunidades
B32: 33_Seguimientos
B33: 40_Estudio_Empresas
B34: 41_Clasificacion_Empresas
B35: 42_Mapa_Mercado
A37: MARKET INTELLIGENCE
B38: 70_Mercado_MGC
B39: 71_Mercado_LNR
B40: 72_Competencia
B41: 73_Campañas
B42: 74_Analisis_Web
B43: 75_Redes_Sociales
B44: 76_CaptaPropIA
A46: NUEVAS FASES OPERATIVAS CAPTAPROPIA / LNH
...

Sheet 00_Indice_V6
A1: ÍNDICE OPERATIVO V6 — SISTEMA ROBINSON CONSOLIDADO
A3: Área | B3: Hoja principal | C3: Función | D3: Estado V6 | E3: Uso | F3: Nota
A4: Dashboard | B4: 00_Dashboard_V4 | C4: Panel ejecutivo consolidado | D4: Núcleo | E4: Abrir primero | F4: Reemplaza dashboards antiguos eliminados
A5: Objetivos | B5: 03_Objetivos_Metas_V4 | C5: Metas mensuales y capital real | D5: Núcleo | E5: Revisión semanal | F5: Conectado a hojas clave
A6: Registro diario | B6: 20_Registro_CEO_V4 | C6: 1 fila = 1 día | D6: Núcleo | E6: Uso diario | F6: Fuente principal de KPI
A7: KPI semanal | B7: 22_KPI_Semanal_V4 | C7: Promedio semanal correcto | D7: Núcleo | E7: Domingo CEO | F7: Separado nota/%/días
A8: KPI mensual | B8: 24_KPI_Mensual_V4 | C8: Score ejecutivo mayo | D8: Núcleo | E8: Cierre mensual | F8: Score limitado a 100%
A9: Balance | B9: 16_Balance_8Col_V4 | C9: Balance 8 columnas | D9: Núcleo | E9: Cierre mensual | F9: Reemplaza balance antiguo eliminado
A10: Deudas | B10: 13_Deudas | C10: Control deuda real | D10: Finanzas | E10: Actualizar pagos/cargos | F10: Reconstruida V6
A11: Conciliación | B11: 15_Conciliacion | C11: Banco real vs Excel | D11: Finanzas | E11: Cierre semanal | F11: Agregar saldos reales
A12: Empresas | B12: 40_Estudio_Empresas | C12: Investigación profunda | D12: Mercado | E12: Antes de CRM | F12: Alimenta oportunidades
A13: Oportunidades | B13: 32_Oportunidades | C13: Pipeline desde empresas A/B | D13: Mercado | E13: Seguimiento | F13: Conectada a estudio
A14: Universidad | B14: 51/53/55/54/58 | C14: Bloques, errores, evaluaciones | D14: Universidad | E14: Diario/semanal | F14: Mantener separado del Ancla
... A111: FASE FIN V7 | B111: 14_Inversiones_BACKUP_V6_8 | C111: Respaldo inversiones | D111: Histórico | E111: Consulta | F111: No editar
A113: Regla V7 | B113: Movimiento ≠ Posición ≠ Rentabilidad ≠ Patrimonio
A115: AUDITORÍA | B115: AUDITORIA_TOTAL_EXCEL_V7_1 | C115: Auditoría completa del libro | D115: Activo | E115: Revisión general | F115: No borrar
A116: CONCLUSIÓN | B116: Excel V7.1 | C116: Sistema de medición amplio y estructuralmente completo | D116: Activo | E116: Pendiente principal: uso y datos reales

Sheet 05_Estructura_Mensual_2026
A1: 05 ESTRUCTURA MENSUAL 2026 — EXCEL MAESTRO, NO ARCHIVOS MENSUALES
A2: Regla: un solo Excel maestro anual. Cada mes funciona como ciclo: Apertura → Registro → Cierre. El historial, patrimonio, CRM, universidad y red se conservan en el mismo archivo.
A4: Mes | B4: Apertura | C4: Registro diario | D4: Finanzas | E4: Empresas / Holding | F4: Universidad | G4: Divina Obsesión | H4: Conciliación | I4: Cierre | J4: Estado | K4: Próximo paso
A5: Mayo | B5: 10_Apertura | C5: 20_Registro_CEO_V4 / 20_Registro_Diario | D5: 11_Ingresos / 12_Gastos / 13_Deudas / 14_Inversiones | E5: 40→41→32→33→30 | F5: 50-58 Universidad | G5: 20 Registro + 21 KPI + 44 Salud | H5: 15_Conciliacion / 18_Conciliacion_Bancaria_V2 | I5: 17_Cierre_Mayo | J5: Cerrado / en revisión | K5: Completar cierre y traspaso a junio
A6: Junio | B6: 25_Control_Junio | C6: 20_Registro_CEO_V4 / 20_Registro_Diario | D6: Ingresos/Gastos por mes = junio | E6: LNH + MGC + LNR + CaptaPropIA | F6: Inicio T2 | G6: Ancla + Salud + Energía | H6: 18_Conciliacion_Bancaria_V2 | I6: Control mensual junio | J6: Activo | K6: Registrar apertura y metas junio
A7: Julio | B7: 26_Control_Julio | C7: 20_Registro_CEO_V4 / 20_Registro_Diario | D7: Ingresos/Gastos por mes = julio | E7: Holding + red + oportunidades | F7: T2 seguimiento | G7: Ancla + KPI personal | H7: 18_Conciliacion_Bancaria_V2 | I7: Control mensual julio | J7: No iniciado | K7: Copiar saldos de cierre junio
A8: Agosto | B8: 27_Control_Agosto | C8: 20_Registro_CEO_V4 / 20_Registro_Diario | D8: Ingresos/Gastos por mes = agosto | E8: Holding + red + oportunidades | F8: T2/T3 según calendario | G8: Ancla + KPI personal | H8: 18_Conciliacion_Bancaria_V2 | I8: Control mensual agosto | J8: No iniciado | K8: Copiar saldos de cierre julio
A9: Septiembre | B9: Ciclo mensual | C9: Registro anual | D9: Ingresos/Gastos por mes | E9: Holding | F9: Universidad | G9: Ancla | H9: Conciliación | I9: Cierre mensual | J9: No iniciado | K9: Preparar cuando corresponda
A10: Octubre | B10: Ciclo mensual | C10: Registro anual | D10: Ingresos/Gastos por mes | E10: Holding | F10: Universidad | G10: Ancla | H10: Conciliación | I10: Cierre mensual | J10: No iniciado | K10: Preparar cuando corresponda
A11: Noviembre | B11: Ciclo mensual | C11: Registro anual | D11: Ingresos/Gastos por mes | E11: Holding | F11: Universidad | G11: Ancla | H11: Conciliación | I11: Cierre mensual | J11: No iniciado | K11: Preparar cuando corresponda
A12: Diciembre | B12: Ciclo mensual | C12: Registro anual | D12: Ingresos/Gastos por mes | E12: Holding | F12: Universidad | G12: Ancla | H12: Conciliación | I12: Cierre anual | J12: No iniciado | K12: Cerrar año 2026

Sheet SEC_01_CEO_CONTROL
A1: CEO & CONTROL CENTRAL
A2: Sección operativa visible. Las hojas históricas/duplicadas fueron enviadas al final y ocultadas.

Sheet 20_Registro_Diario
A1: 20 Registro Diario | N1: Lista Tipo Día | O1: Uso
A2: Registro de ejecución diaria conectado a KPI y Dashboard. | N2: Libre | O2: Día sin turno
N3: Compensado | O3: Día compensado
A4: Fecha | B4: Tipo Día | C4: Dinero | D4: Trabajo | E4: Universidad | F4: Red / MGC | G4: Salud | H4: Acción clave | I4: Nota /10 | J4: Gasto diario | K4: Semana | L4: Comentario | N4: Permiso Administrativo | O4: Permiso
A5: 46143 | B5: Turno de Noche | C5: Sí | D5: Sí | E5: No | F5: Sí | G5: No | H5: Apertura del mes de Mayo | I5: 10 | J5: 421955 | K5: =IF(A5="","", "Semana "&(WEEKNUM(A5,2)-WEEKNUM(DATE(YEAR(A5),MONTH(A5),1),2)+1)) -> Semana 1 | L5: Se realizo la apertura y correciones al excel del mes de mayo | N5: Vacaciones | O5: Vacaciones
A6: 46144 | B6: Turno de Noche | C6: Sí | D6: No | E6: No | F6: No | G6: No | H6: Revision de consolidacion | I6: 10 | J6: =IF(A6="","",SUMIF('12_Gastos'!A:A,A6,'12_Gastos'!D:D)) -> 74130 | K6: =IF(A6="","", "Semana "&(WEEKNUM(A6,2)-WEEKNUM(DATE(YEAR(A6),MONTH(A6),1),2)+1)) -> Semana 1 | L6: Se realizacion de ingreso de consolidacion y comparativa de lo qye tengo, versus lo que deberia tener | N6: Turno de Mañana | O6: 08:00-17:00
A7: 46145 | B7: Turno de Noche | C7: Sí | D7: Sí | E7: Sí | F7: No | G7: No | H7: Registro de gastos | I7: 10 | J7: =IF(A7="","",SUMIF('12_Gastos'!A:A,A7,'12_Gastos'!D:D)) -> 8490 | K7: =IF(A7="","", "Semana "&(WEEKNUM(A7,2)-WEEKNUM(DATE(YEAR(A7),MONTH(A7),1),2)+1)) -> Semana 1 | L7: Se ingresaron los gastos hechos en el dia | N7: Turno de Tarde | O7: 12:00-21:00
A8: 46146 | B8: Libre | C8: Sí | D8: Sí | E8: No | F8: No | G8: No | H8: Registro de ingresos y gastos | I8: 10 | J8: =IF(A8="","",SUMIF('12_Gastos'!A:A,A8,'12_Gastos'!D:D)) -> 52017 | K8: =IF(A8="","", "Semana "&(WEEKNUM(A8,2)-WEEKNUM(DATE(YEAR(A8),MONTH(A8),1),2)+1)) -> Semana 2 | L8: Se actualizo el ultimo ingreso y gastos | N8: Turno de Noche | O8: 21:00-08:00
A9: 46147 | B9: Libre | C9: Sí | D9: Sí | E9: No | F9: Sí | G9: No | H9: Ingreso de contacto CRM | I9: 10 | J9: 456770 | K9: =IF(A9="","", "Semana "&(WEEKNUM(A9,2)-WEEKNUM(DATE(YEAR(A9),MONTH(A9),1),2)+1)) -> Semana 2 | L9: Se probo el sistema, inclyendo Ancla de registro pero hay eficiencias
A10: 46148 | B10: Libre | C10: Sí | D10: Sí | E10: Sí | F10: No | G10: No | H10: Revision de actividades | I10: 10 | J10: =IF(A10="","",SUMIF('12_Gastos'!A:A,A10,'12_Gastos'!D:D)) -> 25290 | K10: =IF(A10="","", "Semana "&(WEEKNUM(A10,2)-WEEKNUM(DATE(YEAR(A10),MONTH(A10),1),2)+1)) -> Semana 2 | L10: Turno extra, solo ingresos y revision de actividades
A11: 46149 | B11: Libre | C11: Sí | D11: Sí | E11: Sí | F11: No | G11: No | H11: Trabajos y pruebas | I11: 10 | J11: =IF(A11="","",SUMIF('12_Gastos'!A:A,A11,'12_Gastos'!D:D)) -> 231720 | K11: =IF(A11="","", "Semana "&(WEEKNUM(A11,2)-WEEKNUM(DATE(YEAR(A11),MONTH(A11),1),2)+1)) -> Semana 2 | L11: Revision de pruebas y trabajos para el fin de semana
A12: 46150 | B12: Turno de Mañana | C12: Sí | D12: Sí | E12: No | F12: No | G12: No | H12: Revision de actividades | I12: 10 | J12: =IF(A12="","",SUMIF('12_Gastos'!A:A,A12,'12_Gastos'!D:D)) -> 29100 | K12: =IF(A12="","", "Semana "&(WEEKNUM(A12,2)-WEEKNUM(DATE(YEAR(A12),MONTH(A12),1),2)+1)) -> Semana 2 | L12: Turno de dia solo reviosn de actividades
A13: 46151 | B13: Turno de Mañana | C13: Sí | D13: Sí | E13: No | F13: No | G13: No | H13: Revision de actividades | I13: 10 | J13: =IF(A13="","",SUMIF('12_Gastos'!A:A,A13,'12_Gastos'!D:D)) -> 5000 | K13: =IF(A13="","", "Semana "&(WEEKNUM(A13,2)-WEEKNUM(DATE(YEAR(A13),MONTH(A13),1),2)+1)) -> Semana 2 | L13: Turno de dia solo reviosn de actividades
A14: 46152 | B14: Turno de Mañana | C14: Sí | D14: Sí | E14: Sí | F14: No | G14: No | H14: Revision de actividades | I14: 10 | J14: =IF(A14="","",SUMIF('12_Gastos'!A:A,A14,'12_Gastos'!D:D)) -> 18000 | K14: =IF(A14="","", "Semana "&(WEEKNUM(A14,2)-WEEKNUM(DATE(YEAR(A14),MONTH(A14),1),2)+1)) -> Semana 2 | L14: Entrega depruebas y trabajos
A15: 46153 | B15: Turno de Mañana | C15: Sí | D15: Sí | E15: No | F15: No | G15: No | H15: Revision de actividades | I15: 10 | J15: =IF(A15="","",SUMIF('12_Gastos'!A:A,A15,'12_Gastos'!D:D)) -> 37225 | K15: =IF(A15="","", "Semana "&(WEEKNUM(A15,2)-WEEKNUM(DATE(YEAR(A15),MONTH(A15),1),2)+1)) -> Semana 3 | L15: Turno de dia solo reviosn de actividades
A16: 46154 | B16: Libre | C16: Sí | D16: No | E16: No | F16: No | G16: No | H16: Re estrucutracion de GPT | I16: 10 | J16: =IF(A16="","",SUMIF('12_Gastos'!A:A,A16,'12_Gastos'!D:D)) -> 13169 | K16: =IF(A16="","", "Semana "&(WEEKNUM(A16,2)-WEEKNUM(DATE(YEAR(A16),MONTH(A16),1),2)+1)) -> Semana 3 | L16: Inicio de reestrcturacion de gpt
A17: 46155 | B17: Libre | C17: Sí | D17: No | E17: No | F17: No | G17: No | H17: Re estrucutracion de GPT | I17: 10 | J17: =IF(A17="","",SUMIF('12_Gastos'!A:A,A17,'12_Gastos'!D:D)) -> 9310 | K17: =IF(A17="","", "Semana "&(WEEKNUM(A17,2)-WEEKNUM(DATE(YEAR(A17),MONTH(A17),1),2)+1)) -> Semana 3 | L17: Inicio de reestrcturacion de gpt
A18: 46156 | B18: Libre | C18: Sí | D18: Sí | E18: No | F18: No | G18: No | H18: Turno extra | I18: 10 | J18: =IF(A18="","",SUMIF('12_Gastos'!A:A,A18,'12_Gastos'!D:D)) -> 15619 | K18: =IF(A18="","", "Semana "&(WEEKNUM(A18,2)-WEEKNUM(DATE(YEAR(A18),MONTH(A18),1),2)+1)) -> Semana 3 | L18: Turno extra, revision de actividades
A19: 46157 | B19: Libre | C19: Sí | D19: Sí | E19: No | F19: No | G19: No | H19: Pago de compromisos | I19: 10 | J19: =IF(A19="","",SUMIF('12_Gastos'!A:A,A19,'12_Gastos'!D:D)) -> 54065 | K19: =IF(A19="","", "Semana "&(WEEKNUM(A19,2)-WEEKNUM(DATE(YEAR(A19),MONTH(A19),1),2)+1)) -> Semana 3 | L19: Pago de compromisos y revision de actividades, turno extra
A20: 46158 | B20: Turno de Noche | C20: Sí | D20: Sí | E20: Sí | F20: No | G20: No | H20: Pago de compromisos | I20: 10 | J20: =IF(A20="","",SUMIF('12_Gastos'!A:A,A20,'12_Gastos'!D:D)) -> 92910 | K20: =IF(A20="","", "Semana "&(WEEKNUM(A20,2)-WEEKNUM(DATE(YEAR(A20),MONTH(A20),1),2)+1)) -> Semana 3 | L20: Pago de compromisos y revision de actividades, estudio
A21: 46159 | B21: Turno de Noche | C21: Sí | D21: Sí | E21: Sí | F21: No | G21: No | H21: Trabajos y pruebas | I21: 10 | J21: =IF(A21="","",SUMIF('12_Gastos'!A:A,A21,'12_Gastos'!D:D)) -> 850 | K21: =IF(A21="","", "Semana "&(WEEKNUM(A21,2)-WEEKNUM(DATE(YEAR(A21),MONTH(A21),1),2)+1)) -> Semana 3 | L21: Entrega de trabajos y pruebas
... A52: 46190 | B52: Turno de Noche | C52: Sí | D52: Sí | E52: Sí | F52: No | G52: No | H52: Estudio de Probabilidad y estadisticas | I52: 10 | J52: =IF(A52="","",SUMIF('12_Gastos'!A:A,A52,'12_Gastos'!D:D)) -> 18910 | K52: =IF(A52="","", "Semana "&(WEEKNUM(A52,2)-WEEKNUM(DATE(YEAR(A52),MONTH(A52),1),2)+1)) -> Semana 3 | L52: Redaccion del manual de estudio completo
A53: 46191 | B53: Libre | C53: Sí | D53: No | E53: Sí | F53: No | G53: Sí | H53: Revision de excel, correccion del mismo | I53: 10 | K53: =IF(A53="","", "Semana "&(WEEKNUM(A53,2)-WEEKNUM(DATE(YEAR(A53),MONTH(A53),1),2)+1)) -> Semana 3 | L53: Registro de estudios, toma de presion y nuevo formato
A54: 46192 | B54: Compensado | C54: Sí | D54: No | E54: No | F54: No | G54: No | H54: Finiquito y comras | I54: 8 | K54: =IF(A54="","", "Semana "&(WEEKNUM(A54,2)-WEEKNUM(DATE(YEAR(A54),MONTH(A54),1),2)+1)) -> Semana 3 | L54: Retiro y cobro de finiquito y compra
A55: 46193 | B55: Libre | C55: Sí | D55: No | E55: No | F55: No | G55: No | H55: Compras y preparacion dia padre | I55: 7 | J55: =IF(A55="","",SUMIF('12_Gastos'!A:A,A55,'12_Gastos'!D:D)) -> 0 | K55: =IF(A55="","", "Semana "&(WEEKNUM(A55,2)-WEEKNUM(DATE(YEAR(A55),MONTH(A55),1),2)+1)) -> Semana 3 | L55: Compras y preparacion dia del padre
A56: 46194 | B56: Turno de Noche | C56: Sí | D56: Sí | E56: Sí | F56: No | G56: No | H56: Pruebas | I56: 5 | J56: =IF($A56="","",SUMIF('12_Gastos'!$A:$A,$A56,'12_Gastos'!$D:$D)) -> 202150 | K56: =IF($A56="","","Semana "&(WEEKNUM($A56,2)-WEEKNUM(DATE(YEAR($A56),MONTH($A56),1),2)+1)) -> Semana 3 | L56: Pruebas universidad
A57: 46195 | B57: Libre | C57: Sí | D57: No | E57: Sí | F57: Sí | G57: No | H57: Estudios | I57: 10 | J57: =IF(A56="","",SUMIF('12_Gastos'!A:A,A56,'12_Gastos'!D:D)) -> 202150 | K57: =IF(A56="","", "Semana "&(WEEKNUM(A56,2)-WEEKNUM(DATE(YEAR(A56),MONTH(A56),1),2)+1)) -> Semana 3 | L57: Registros
